Workbook

Sheet Referensi Manual
A1: REFERENSI MANUAL PUNCAK KEPALA | B1: REFERENSI MANUAL PUNCAK KEPALA | C1: REFERENSI MANUAL PUNCAK KEPALA | D1: REFERENSI MANUAL PUNCAK KEPALA | E1: REFERENSI MANUAL PUNCAK KEPALA
A2: Tandai satu kali puncak kepala pada citra warp PX 120. Nilai ini dipakai sebagai pembanding yang sama untuk seluruh 9 kombinasi.
A4: No. | B4: Kode citra | C4: Y puncak kepala manual (px) | D4: Cara anotasi | E4: Catatan
A5: 1 | B5: C01 | D5: Piksel paling atas kepala pada citra warp PX 120
A6: 2 | B6: C02 | D6: Piksel paling atas kepala pada citra warp PX 120
A7: 3 | B7: C03 | D7: Piksel paling atas kepala pada citra warp PX 120
A8: 4 | B8: C04 | D8: Piksel paling atas kepala pada citra warp PX 120
A9: 5 | B9: C05 | D9: Piksel paling atas kepala pada citra warp PX 120
A10: 6 | B10: C06 | D10: Piksel paling atas kepala pada citra warp PX 120
A11: 7 | B11: C07 | D11: Piksel paling atas kepala pada citra warp PX 120
A12: 8 | B12: C08 | D12: Piksel paling atas kepala pada citra warp PX 120
A13: 9 | B13: C09 | D13: Piksel paling atas kepala pada citra warp PX 120
A14: 10 | B14: C10 | D14: Piksel paling atas kepala pada citra warp PX 120
A15: 11 | B15: C11 | D15: Piksel paling atas kepala pada citra warp PX 120
A16: 12 | B16: C12 | D16: Piksel paling atas kepala pada citra warp PX 120
... A19: 15 | B19: C15 | D19: Piksel paling atas kepala pada citra warp PX 120

Sheet Data 135 Pengamatan
A1: DATA PENGUJIAN 9 KOMBINASI KOEFISIEN KEPALA × 15 FOTO | B1: DATA PENGUJIAN 9 KOMBINASI KOEFISIEN KEPALA × 15 FOTO | C1: DATA PENGUJIAN 9 KOMBINASI KOEFISIEN KEPALA × 15 FOTO | D1: DATA PENGUJIAN 9 KOMBINASI KOEFISIEN KEPALA × 15 FOTO | E1: DATA PENGUJIAN 9 KOMBINASI KOEFISIEN KEPALA × 15 FOTO | F1: DATA PENGUJIAN 9 KOMBINASI KOEFISIEN KEPALA × 15 FOTO | G1: DATA PENGUJIAN 9 KOMBINASI KOEFISIEN KEPALA × 15 FOTO | H1: DATA PENGUJIAN 9 KOMBINASI KOEFISIEN KEPALA × 15 FOTO | I1: DATA PENGUJIAN 9 KOMBINASI KOEFISIEN KEPALA × 15 FOTO | J1: DATA PENGUJIAN 9 KOMBINASI KOEFISIEN KEPALA × 15 FOTO | K1: DATA PENGUJIAN 9 KOMBINASI KOEFISIEN KEPALA × 15 FOTO | L1: DATA PENGUJIAN 9 KOMBINASI KOEFISIEN KEPALA × 15 FOTO
A2: Isi kolom kuning dari screenshot Measurement. Kolom biru dihitung otomatis. Jangan menilai kombinasi dari tinggi akhir; gunakan galat headTop.y.
A4: No. | B4: Kombinasi | C4: eyeToShoulder | D4: earToEye | E4: Kode citra | F4: headTop.y aplikasi (px) | G4: Y kepala manual (px) | H4: Galat kepala (px) | I4: Tinggi aplikasi (cm) | J4: Measurement tersedia | K4: Bukti tahap lengkap | L4: Catatan
A5: 1 | B5: 0,20 / 0,10 | C5: 0.2 | D5: 0.1 | E5: C01 | G5: =IF('Referensi Manual'!C5="","",'Referensi Manual'!C5) | H5: =IF(OR(F5="",G5=""),"",ABS(F5-G5)) | J5: Ya | K5: Ya
A6: 2 | B6: 0,20 / 0,10 | C6: 0.2 | D6: 0.1 | E6: C02 | G6: =IF('Referensi Manual'!C6="","",'Referensi Manual'!C6) | H6: =IF(OR(F6="",G6=""),"",ABS(F6-G6)) | J6: Ya | K6: Ya
A7: 3 | B7: 0,20 / 0,10 | C7: 0.2 | D7: 0.1 | E7: C03 | G7: =IF('Referensi Manual'!C7="","",'Referensi Manual'!C7) | H7: =IF(OR(F7="",G7=""),"",ABS(F7-G7)) | J7: Ya | K7: Ya
A8: 4 | B8: 0,20 / 0,10 | C8: 0.2 | D8: 0.1 | E8: C04 | G8: =IF('Referensi Manual'!C8="","",'Referensi Manual'!C8) | H8: =IF(OR(F8="",G8=""),"",ABS(F8-G8)) | J8: Ya | K8: Ya
A9: 5 | B9: 0,20 / 0,10 | C9: 0.2 | D9: 0.1 | E9: C05 | G9: =IF('Referensi Manual'!C9="","",'Referensi Manual'!C9) | H9: =IF(OR(F9="",G9=""),"",ABS(F9-G9)) | J9: Ya | K9: Ya
A10: 6 | B10: 0,20 / 0,10 | C10: 0.2 | D10: 0.1 | E10: C06 | G10: =IF('Referensi Manual'!C10="","",'Referensi Manual'!C10) | H10: =IF(OR(F10="",G10=""),"",ABS(F10-G10)) | J10: Ya | K10: Ya
A11: 7 | B11: 0,20 / 0,10 | C11: 0.2 | D11: 0.1 | E11: C07 | G11: =IF('Referensi Manual'!C11="","",'Referensi Manual'!C11) | H11: =IF(OR(F11="",G11=""),"",ABS(F11-G11)) | J11: Ya | K11: Ya
A12: 8 | B12: 0,20 / 0,10 | C12: 0.2 | D12: 0.1 | E12: C08 | G12: =IF('Referensi Manual'!C12="","",'Referensi Manual'!C12) | H12: =IF(OR(F12="",G12=""),"",ABS(F12-G12)) | J12: Ya | K12: Ya
A13: 9 | B13: 0,20 / 0,10 | C13: 0.2 | D13: 0.1 | E13: C09 | G13: =IF('Referensi Manual'!C13="","",'Referensi Manual'!C13) | H13: =IF(OR(F13="",G13=""),"",ABS(F13-G13)) | J13: Ya | K13: Ya
A14: 10 | B14: 0,20 / 0,10 | C14: 0.2 | D14: 0.1 | E14: C10 | G14: =IF('Referensi Manual'!C14="","",'Referensi Manual'!C14) | H14: =IF(OR(F14="",G14=""),"",ABS(F14-G14)) | J14: Ya | K14: Ya
A15: 11 | B15: 0,20 / 0,10 | C15: 0.2 | D15: 0.1 | E15: C11 | G15: =IF('Referensi Manual'!C15="","",'Referensi Manual'!C15) | H15: =IF(OR(F15="",G15=""),"",ABS(F15-G15)) | J15: Ya | K15: Ya
A16: 12 | B16: 0,20 / 0,10 | C16: 0.2 | D16: 0.1 | E16: C12 | G16: =IF('Referensi Manual'!C16="","",'Referensi Manual'!C16) | H16: =IF(OR(F16="",G16=""),"",ABS(F16-G16)) | J16: Ya | K16: Ya
... A19: 15 | B19: 0,20 / 0,10 | C19: 0.2 | D19: 0.1 | E19: C15 | G19: =IF('Referensi Manual'!C19="","",'Referensi Manual'!C19) | H19: =IF(OR(F19="",G19=""),"",ABS(F19-G19)) | J19: Ya | K19: Ya
A20: 16 | B20: 0,20 / 0,15 | C20: 0.2 | D20: 0.15 | E20: C01 | G20: =IF('Referensi Manual'!C5="","",'Referensi Manual'!C5) | H20: =IF(OR(F20="",G20=""),"",ABS(F20-G20)) | J20: Ya | K20: Ya
A21: 17 | B21: 0,20 / 0,15 | C21: 0.2 | D21: 0.15 | E21: C02 | G21: =IF('Referensi Manual'!C6="","",'Referensi Manual'!C6) | H21: =IF(OR(F21="",G21=""),"",ABS(F21-G21)) | J21: Ya | K21: Ya
A22: 18 | B22: 0,20 / 0,15 | C22: 0.2 | D22: 0.15 | E22: C03 | G22: =IF('Referensi Manual'!C7="","",'Referensi Manual'!C7) | H22: =IF(OR(F22="",G22=""),"",ABS(F22-G22)) | J22: Ya | K22: Ya
A23: 19 | B23: 0,20 / 0,15 | C23: 0.2 | D23: 0.15 | E23: C04 | G23: =IF('Referensi Manual'!C8="","",'Referensi Manual'!C8) | H23: =IF(OR(F23="",G23=""),"",ABS(F23-G23)) | J23: Ya | K23: Tidak | L23: Screenshot MediaPipe tidak tersimpan; Measurement tersedia sehingga galat kepala tetap dapat dihitung.
A24: 20 | B24: 0,20 / 0,15 | C24: 0.2 | D24: 0.15 | E24: C05 | G24: =IF('Referensi Manual'!C9="","",'Referensi Manual'!C9) | H24: =IF(OR(F24="",G24=""),"",ABS(F24-G24)) | J24: Ya | K24: Ya
A25: 21 | B25: 0,20 / 0,15 | C25: 0.2 | D25: 0.15 | E25: C06 | G25: =IF('Referensi Manual'!C10="","",'Referensi Manual'!C10) | H25: =IF(OR(F25="",G25=""),"",ABS(F25-G25)) | J25: Ya | K25: Ya
A26: 22 | B26: 0,20 / 0,15 | C26: 0.2 | D26: 0.15 | E26: C07 | G26: =IF('Referensi Manual'!C11="","",'Referensi Manual'!C11) | H26: =IF(OR(F26="",G26=""),"",ABS(F26-G26)) | J26: Ya | K26: Ya
A27: 23 | B27: 0,20 / 0,15 | C27: 0.2 | D27: 0.15 | E27: C08 | G27: =IF('Referensi Manual'!C12="","",'Referensi Manual'!C12) | H27: =IF(OR(F27="",G27=""),"",ABS(F27-G27)) | J27: Ya | K27: Ya
A28: 24 | B28: 0,20 / 0,15 | C28: 0.2 | D28: 0.15 | E28: C09 | G28: =IF('Referensi Manual'!C13="","",'Referensi Manual'!C13) | H28: =IF(OR(F28="",G28=""),"",ABS(F28-G28)) | J28: Ya | K28: Ya
A29: 25 | B29: 0,20 / 0,15 | C29: 0.2 | D29: 0.15 | E29: C10 | G29: =IF('Referensi Manual'!C14="","",'Referensi Manual'!C14) | H29: =IF(OR(F29="",G29=""),"",ABS(F29-G29)) | J29: Ya | K29: Ya
A30: 26 | B30: 0,20 / 0,15 | C30: 0.2 | D30: 0.15 | E30: C11 | G30: =IF('Referensi Manual'!C15="","",'Referensi Manual'!C15) | H30: =IF(OR(F30="",G30=""),"",ABS(F30-G30)) | J30: Ya | K30: Ya
A31: 27 | B31: 0,20 / 0,15 | C31: 0.2 | D31: 0.15 | E31: C12 | G31: =IF('Referensi Manual'!C16="","",'Referensi Manual'!C16) | H31: =IF(OR(F31="",G31=""),"",ABS(F31-G31)) | J31: Ya | K31: Ya
A32: 28 | B32: 0,20 / 0,15 | C32: 0.2 | D32: 0.15 | E32: C13 | G32: =IF('Referensi Manual'!C17="","",'Referensi Manual'!C17) | H32: =IF(OR(F32="",G32=""),"",ABS(F32-G32)) | J32: Ya | K32: Tidak | L32: Screenshot MediaPipe tidak tersimpan; Measurement tersedia sehingga galat kepala tetap dapat dihitung.
A33: 29 | B33: 0,20 / 0,15 | C33: 0.2 | D33: 0.15 | E33: C14 | G33: =IF('Referensi Manual'!C18="","",'Referensi Manual'!C18) | H33: =IF(OR(F33="",G33=""),"",ABS(F33-G33)) | J33: Ya | K33: Ya
A34: 30 | B34: 0,20 / 0,15 | C34: 0.2 | D34: 0.15 | E34: C15 | G34: =IF('Referensi Manual'!C19="","",'Referensi Manual'!C19) | H34: =IF(OR(F34="",G34=""),"",ABS(F34-G34)) | J34: Ya | K34: Ya
A35: 31 | B35: 0,20 / 0,20 | C35: 0.2 | D35: 0.2 | E35: C01 | G35: =IF('Referensi Manual'!C5="","",'Referensi Manual'!C5) | H35: =IF(OR(F35="",G35=""),"",ABS(F35-G35)) | J35: Ya | K35: Ya
A36: 32 | B36: 0,20 / 0,20 | C36: 0.2 | D36: 0.2 | E36: C02 | G36: =IF('Referensi Manual'!C6="","",'Referensi Manual'!C6) | H36: =IF(OR(F36="",G36=""),"",ABS(F36-G36)) | J36: Ya | K36: Ya
A37: 33 | B37: 0,20 / 0,20 | C37: 0.2 | D37: 0.2 | E37: C03 | G37: =IF('Referensi Manual'!C7="","",'Referensi Manual'!C7) | H37: =IF(OR(F37="",G37=""),"",ABS(F37-G37)) | J37: Ya | K37: Ya
A38: 34 | B38: 0,20 / 0,20 | C38: 0.2 | D38: 0.2 | E38: C04 | G38: =IF('Referensi Manual'!C8="","",'Referensi Manual'!C8) | H38: =IF(OR(F38="",G38=""),"",ABS(F38-G38)) | J38: Ya | K38: Ya
A39: 35 | B39: 0,20 / 0,20 | C39: 0.2 | D39: 0.2 | E39: C05 | G39: =IF('Referensi Manual'!C9="","",'Referensi Manual'!C9) | H39: =IF(OR(F39="",G39=""),"",ABS(F39-G39)) | J39: Ya | K39: Ya
A40: 36 | B40: 0,20 / 0,20 | C40: 0.2 | D40: 0.2 | E40: C06 | G40: =IF('Referensi Manual'!C10="","",'Referensi Manual'!C10) | H40: =IF(OR(F40="",G40=""),"",ABS(F40-G40)) | J40: Ya | K40: Ya
A41: 37 | B41: 0,20 / 0,20 | C41: 0.2 | D41: 0.2 | E41: C07 | G41: =IF('Referensi Manual'!C11="","",'Referensi Manual'!C11) | H41: =IF(OR(F41="",G41=""),"",ABS(F41-G41)) | J41: Ya | K41: Ya
A42: 38 | B42: 0,20 / 0,20 | C42: 0.2 | D42: 0.2 | E42: C08 | G42: =IF('Referensi Manual'!C12="","",'Referensi Manual'!C12) | H42: =IF(OR(F42="",G42=""),"",ABS(F42-G42)) | J42: Ya | K42: Ya
A43: 39 | B43: 0,20 / 0,20 | C43: 0.2 | D43: 0.2 | E43: C09 | G43: =IF('Referensi Manual'!C13="","",'Referensi Manual'!C13) | H43: =IF(OR(F43="",G43=""),"",ABS(F43-G43)) | J43: Ya | K43: Ya
...

Sheet Ringkasan Kombinasi
A1: RINGKASAN DAN PEMILIHAN KOEFISIEN KEPALA | B1: RINGKASAN DAN PEMILIHAN KOEFISIEN KEPALA | C1: RINGKASAN DAN PEMILIHAN KOEFISIEN KEPALA | D1: RINGKASAN DAN PEMILIHAN KOEFISIEN KEPALA | E1: RINGKASAN DAN PEMILIHAN KOEFISIEN KEPALA | F1: RINGKASAN DAN PEMILIHAN KOEFISIEN KEPALA | G1: RINGKASAN DAN PEMILIHAN KOEFISIEN KEPALA | H1: RINGKASAN DAN PEMILIHAN KOEFISIEN KEPALA
A3: Peringkat | B3: Kombinasi | C3: eyeToShoulder | D3: earToEye | E3: Data terisi | F3: Rata-rata galat (px) | G3: Galat maksimum (px) | H3: Keputusan
A4: =IF(E4=0,"",RANK(F4,$F$4:$F$12,1)) | B4: 0,20 / 0,10 | C4: 0.2 | D4: 0.1 | E4: =COUNT('Data 135 Pengamatan'!H5:H19) -> 0 | F4: =IF(E4=0,"",AVERAGE('Data 135 Pengamatan'!H5:H19)) | G4: =IF(E4=0,"",MAX('Data 135 Pengamatan'!H5:H19)) | H4: =IF(E4<15,"BELUM LENGKAP",IF(A4=1,"TERBAIK","") ) -> BELUM LENGKAP
A5: =IF(E5=0,"",RANK(F5,$F$4:$F$12,1)) | B5: 0,20 / 0,15 | C5: 0.2 | D5: 0.15 | E5: =COUNT('Data 135 Pengamatan'!H20:H34) -> 0 | F5: =IF(E5=0,"",AVERAGE('Data 135 Pengamatan'!H20:H34)) | G5: =IF(E5=0,"",MAX('Data 135 Pengamatan'!H20:H34)) | H5: =IF(E5<15,"BELUM LENGKAP",IF(A5=1,"TERBAIK","") ) -> BELUM LENGKAP
A6: =IF(E6=0,"",RANK(F6,$F$4:$F$12,1)) | B6: 0,20 / 0,20 | C6: 0.2 | D6: 0.2 | E6: =COUNT('Data 135 Pengamatan'!H35:H49) -> 0 | F6: =IF(E6=0,"",AVERAGE('Data 135 Pengamatan'!H35:H49)) | G6: =IF(E6=0,"",MAX('Data 135 Pengamatan'!H35:H49)) | H6: =IF(E6<15,"BELUM LENGKAP",IF(A6=1,"TERBAIK","") ) -> BELUM LENGKAP
A7: =IF(E7=0,"",RANK(F7,$F$4:$F$12,1)) | B7: 0,28 / 0,10 | C7: 0.28 | D7: 0.1 | E7: =COUNT('Data 135 Pengamatan'!H50:H64) -> 0 | F7: =IF(E7=0,"",AVERAGE('Data 135 Pengamatan'!H50:H64)) | G7: =IF(E7=0,"",MAX('Data 135 Pengamatan'!H50:H64)) | H7: =IF(E7<15,"BELUM LENGKAP",IF(A7=1,"TERBAIK","") ) -> BELUM LENGKAP
A8: =IF(E8=0,"",RANK(F8,$F$4:$F$12,1)) | B8: 0,28 / 0,15 | C8: 0.28 | D8: 0.15 | E8: =COUNT('Data 135 Pengamatan'!H65:H79) -> 0 | F8: =IF(E8=0,"",AVERAGE('Data 135 Pengamatan'!H65:H79)) | G8: =IF(E8=0,"",MAX('Data 135 Pengamatan'!H65:H79)) | H8: =IF(E8<15,"BELUM LENGKAP",IF(A8=1,"TERBAIK","") ) -> BELUM LENGKAP
A9: =IF(E9=0,"",RANK(F9,$F$4:$F$12,1)) | B9: 0,28 / 0,20 | C9: 0.28 | D9: 0.2 | E9: =COUNT('Data 135 Pengamatan'!H80:H94) -> 0 | F9: =IF(E9=0,"",AVERAGE('Data 135 Pengamatan'!H80:H94)) | G9: =IF(E9=0,"",MAX('Data 135 Pengamatan'!H80:H94)) | H9: =IF(E9<15,"BELUM LENGKAP",IF(A9=1,"TERBAIK","") ) -> BELUM LENGKAP
A10: =IF(E10=0,"",RANK(F10,$F$4:$F$12,1)) | B10: 0,35 / 0,10 | C10: 0.35 | D10: 0.1 | E10: =COUNT('Data 135 Pengamatan'!H95:H109) -> 0 | F10: =IF(E10=0,"",AVERAGE('Data 135 Pengamatan'!H95:H109)) | G10: =IF(E10=0,"",MAX('Data 135 Pengamatan'!H95:H109)) | H10: =IF(E10<15,"BELUM LENGKAP",IF(A10=1,"TERBAIK","") ) -> BELUM LENGKAP
A11: =IF(E11=0,"",RANK(F11,$F$4:$F$12,1)) | B11: 0,35 / 0,15 | C11: 0.35 | D11: 0.15 | E11: =COUNT('Data 135 Pengamatan'!H110:H124) -> 0 | F11: =IF(E11=0,"",AVERAGE('Data 135 Pengamatan'!H110:H124)) | G11: =IF(E11=0,"",MAX('Data 135 Pengamatan'!H110:H124)) | H11: =IF(E11<15,"BELUM LENGKAP",IF(A11=1,"TERBAIK","") ) -> BELUM LENGKAP
A12: =IF(E12=0,"",RANK(F12,$F$4:$F$12,1)) | B12: 0,35 / 0,20 | C12: 0.35 | D12: 0.2 | E12: =COUNT('Data 135 Pengamatan'!H125:H139) -> 0 | F12: =IF(E12=0,"",AVERAGE('Data 135 Pengamatan'!H125:H139)) | G12: =IF(E12=0,"",MAX('Data 135 Pengamatan'!H125:H139)) | H12: =IF(E12<15,"BELUM LENGKAP",IF(A12=1,"TERBAIK","") ) -> BELUM LENGKAP
A15: Syarat keputusan: setiap kombinasi harus memiliki 15 nilai headTop.y aplikasi dan 15 referensi manual. Nilai dengan rata-rata galat terkecil dipilih.

Sheet Petunjuk
A1: PETUNJUK PENGISIAN DAN RUMUS | B1: PETUNJUK PENGISIAN DAN RUMUS | C1: PETUNJUK PENGISIAN DAN RUMUS | D1: PETUNJUK PENGISIAN DAN RUMUS
A3: Langkah | B3: Yang dilakukan | C3: Rumus / sumber | D3: Catatan
A4: 1 | B4: Isi Y kepala manual C01–C15 satu kali. | C4: Piksel paling atas kepala pada citra warp PX 120 | D4: Gunakan anotasi yang sama untuk 9 kombinasi.
A5: 2 | B5: Buka screenshot Measurement tiap kombinasi dan foto. | C5: Salin angka headTop.y | D5: Total 135 nilai aplikasi.
A6: 3 | B6: Isi tinggi aplikasi sebagai data pendukung. | C6: Angka Tinggi badan pada Measurement | D6: Bukan dasar memilih koefisien.
A7: 4 | B7: Galat dihitung otomatis. | C7: ABS(Y aplikasi − Y manual) | D7: Satuan piksel.
A8: 5 | B8: Periksa Data terisi pada Ringkasan. | C8: Harus 15 untuk setiap kombinasi | D8: Jangan memilih hasil dari sampel tidak lengkap.
A9: 6 | B9: Pilih peringkat 1. | C9: Rata-rata galat piksel paling kecil | D9: Kunci koefisien sebelum uji titik kaki.
A10: 7 | B10: Tiga bukti tahap antara tidak lengkap. | C10: C04/C13 0,20–0,15 dan C13 0,28–0,10 | D10: Measurement tetap tersedia sehingga data utama valid.
